2021-03-17 11:36:03,307 - ServiceNode - INFO : [EtcdSupport.py:474]: we have create ServiceRegister, wait 5 seconds
2021-03-17 11:36:03,309 - ServiceNode - INFO : [EtcdSupport.py:477]: we have create ServiceFinder
2021-03-17 11:36:04,325 - ServiceRegister - ERROR : [EtcdSupport.py:155]: regist service : BattleAllocatorStub error
2021-03-17 11:36:04,326 - ServiceRegister - ERROR : on_traceback, type:<class 'requests.exceptions.ConnectionError'>, value:HTTPConnectionPool(host='127.0.0.1', port=2379): Max retries exceeded with url: /v2/keys/services/BattleAllocatorStub/127.0.0.1%7C9000 (Caused by NewConnectionError('<urllib3.connection.HTTPConnection object at 0x00000202ED441670>: Failed to establish a new connection: [WinError 10061] 由于目标计算机积极拒绝，无法连接。')), traceback:<class 'requests.exceptions.ConnectionError'>
HTTPConnectionPool(host='127.0.0.1', port=2379): Max retries exceeded with url: /v2/keys/services/BattleAllocatorStub/127.0.0.1%7C9000 (Caused by NewConnectionError('<urllib3.connection.HTTPConnection object at 0x00000202ED441670>: Failed to establish a new connection: [WinError 10061] 由于目标计算机积极拒绝，无法连接。'))
  File "D:\Documents\github\realtime-server\pycharm2020.1.3\script\core\EtcdSupport.py", line 143, in _do_regist
    locals={'self': <core.EtcdSupport.ServiceRegister object at 0x00000202ED390D90>, 'service_name': 'BattleAllocatorStub', 'data': 'ttl=180', 'now_url': 'http://127.0.0.1:2379/v2/keys/services/BattleAllocatorStub/127.0.0.1|9000'}
  File "C:\Program Files\Python38\lib\concurrent\futures\thread.py", line 57, in run
    locals={}
  File "D:\Documents\github\realtime-server\pycharm2020.1.3\script\core\EtcdSupport.py", line 144, in <lambda>
    locals={'data': 'ttl=180', 'now_url': 'http://127.0.0.1:2379/v2/keys/services/BattleAllocatorStub/127.0.0.1|9000'}
  File "C:\Program Files\Python38\lib\site-packages\requests\api.py", line 61, in request
    locals={'method': 'PUT', 'url': 'http://127.0.0.1:2379/v2/keys/services/BattleAllocatorStub/127.0.0.1|9000', 'kwargs': {'data': 'ttl=180', 'headers': {'Content-Type': 'application/x-www-form-urlencoded'}, 'timeout': 2}, 'session': <requests.sessions.Session object at 0x00000202ED42F070>}
  File "C:\Program Files\Python38\lib\site-packages\requests\sessions.py", line 542, in request
    locals={'self': <requests.sessions.Session object at 0x00000202ED42F070>, 'method': 'PUT', 'url': 'http://127.0.0.1:2379/v2/keys/services/BattleAllocatorStub/127.0.0.1|9000', 'params': None, 'data': 'ttl=180', 'headers': {'Content-Type': 'application/x-www-form-urlencoded'}, 'cookies': None, 'files': None, 'auth': None, 'timeout': 2, 'allow_redirects': True, 'proxies': {}, 'hooks': None, 'stream': None, 'verify': None, 'cert': None, 'json': None, 'req': <Request [PUT]>, 'prep': <PreparedRequest [PUT]>, 'settings': {'verify': True, 'proxies': OrderedDict(), 'stream': False, 'cert': None}, 'send_kwargs': {'timeout': 2, 'allow_redirects': True, 'verify': True, 'proxies': OrderedDict(), 'stream': False, 'cert': None}}
  File "C:\Program Files\Python38\lib\site-packages\requests\sessions.py", line 655, in send
    locals={'self': <requests.sessions.Session object at 0x00000202ED42F070>, 'request': <PreparedRequest [PUT]>, 'kwargs': {'timeout': 2, 'verify': True, 'proxies': OrderedDict(), 'stream': False, 'cert': None}, 'allow_redirects': True, 'stream': False, 'hooks': {'response': []}, 'adapter': <requests.adapters.HTTPAdapter object at 0x00000202ED42F280>, 'start': 0.197542996}
  File "C:\Program Files\Python38\lib\site-packages\requests\adapters.py", line 516, in send
    locals={'self': <requests.adapters.HTTPAdapter object at 0x00000202ED42F280>, 'request': <PreparedRequest [PUT]>, 'stream': False, 'timeout': Timeout(connect=2, read=2, total=None), 'verify': True, 'cert': None, 'proxies': OrderedDict(), 'conn': <urllib3.connectionpool.HTTPConnectionPool object at 0x00000202ED42F580>, 'url': '/v2/keys/services/BattleAllocatorStub/127.0.0.1%7C9000', 'chunked': False}
2021-03-17 11:43:36,448 - ServiceNode - INFO : [EtcdSupport.py:474]: we have create ServiceRegister, wait 5 seconds
2021-03-17 11:43:36,449 - ServiceNode - INFO : [EtcdSupport.py:477]: we have create ServiceFinder
2021-03-17 11:43:37,463 - ServiceRegister - ERROR : [EtcdSupport.py:155]: regist service : BattleAllocatorStub error
2021-03-17 11:43:37,463 - ServiceRegister - ERROR : on_traceback, type:<class 'requests.exceptions.ConnectionError'>, value:HTTPConnectionPool(host='127.0.0.1', port=2379): Max retries exceeded with url: /v2/keys/services/BattleAllocatorStub/127.0.0.1%7C9000 (Caused by NewConnectionError('<urllib3.connection.HTTPConnection object at 0x0000022416221670>: Failed to establish a new connection: [WinError 10061] 由于目标计算机积极拒绝，无法连接。')), traceback:<class 'requests.exceptions.ConnectionError'>
HTTPConnectionPool(host='127.0.0.1', port=2379): Max retries exceeded with url: /v2/keys/services/BattleAllocatorStub/127.0.0.1%7C9000 (Caused by NewConnectionError('<urllib3.connection.HTTPConnection object at 0x0000022416221670>: Failed to establish a new connection: [WinError 10061] 由于目标计算机积极拒绝，无法连接。'))
  File "D:\Documents\github\realtime-server\pycharm2020.1.3\script\core\EtcdSupport.py", line 143, in _do_regist
    locals={'self': <core.EtcdSupport.ServiceRegister object at 0x0000022416170D90>, 'service_name': 'BattleAllocatorStub', 'data': 'ttl=180', 'now_url': 'http://127.0.0.1:2379/v2/keys/services/BattleAllocatorStub/127.0.0.1|9000'}
  File "C:\Program Files\Python38\lib\concurrent\futures\thread.py", line 57, in run
    locals={}
  File "D:\Documents\github\realtime-server\pycharm2020.1.3\script\core\EtcdSupport.py", line 144, in <lambda>
    locals={'data': 'ttl=180', 'now_url': 'http://127.0.0.1:2379/v2/keys/services/BattleAllocatorStub/127.0.0.1|9000'}
  File "C:\Program Files\Python38\lib\site-packages\requests\api.py", line 61, in request
    locals={'method': 'PUT', 'url': 'http://127.0.0.1:2379/v2/keys/services/BattleAllocatorStub/127.0.0.1|9000', 'kwargs': {'data': 'ttl=180', 'headers': {'Content-Type': 'application/x-www-form-urlencoded'}, 'timeout': 2}, 'session': <requests.sessions.Session object at 0x000002241620F070>}
  File "C:\Program Files\Python38\lib\site-packages\requests\sessions.py", line 542, in request
    locals={'self': <requests.sessions.Session object at 0x000002241620F070>, 'method': 'PUT', 'url': 'http://127.0.0.1:2379/v2/keys/services/BattleAllocatorStub/127.0.0.1|9000', 'params': None, 'data': 'ttl=180', 'headers': {'Content-Type': 'application/x-www-form-urlencoded'}, 'cookies': None, 'files': None, 'auth': None, 'timeout': 2, 'allow_redirects': True, 'proxies': {}, 'hooks': None, 'stream': None, 'verify': None, 'cert': None, 'json': None, 'req': <Request [PUT]>, 'prep': <PreparedRequest [PUT]>, 'settings': {'verify': True, 'proxies': OrderedDict(), 'stream': False, 'cert': None}, 'send_kwargs': {'timeout': 2, 'allow_redirects': True, 'verify': True, 'proxies': OrderedDict(), 'stream': False, 'cert': None}}
  File "C:\Program Files\Python38\lib\site-packages\requests\sessions.py", line 655, in send
    locals={'self': <requests.sessions.Session object at 0x000002241620F070>, 'request': <PreparedRequest [PUT]>, 'kwargs': {'timeout': 2, 'verify': True, 'proxies': OrderedDict(), 'stream': False, 'cert': None}, 'allow_redirects': True, 'stream': False, 'hooks': {'response': []}, 'adapter': <requests.adapters.HTTPAdapter object at 0x000002241620F280>, 'start': 0.202035684}
  File "C:\Program Files\Python38\lib\site-packages\requests\adapters.py", line 516, in send
    locals={'self': <requests.adapters.HTTPAdapter object at 0x000002241620F280>, 'request': <PreparedRequest [PUT]>, 'stream': False, 'timeout': Timeout(connect=2, read=2, total=None), 'verify': True, 'cert': None, 'proxies': OrderedDict(), 'conn': <urllib3.connectionpool.HTTPConnectionPool object at 0x000002241620F580>, 'url': '/v2/keys/services/BattleAllocatorStub/127.0.0.1%7C9000', 'chunked': False}
2021-03-17 11:43:38,477 - ServiceRegister - ERROR : [EtcdSupport.py:155]: regist service : BattleAllocatorStub error
2021-03-17 11:43:38,477 - ServiceRegister - ERROR : on_traceback, type:<class 'requests.exceptions.ConnectionError'>, value:HTTPConnectionPool(host='127.0.0.1', port=2379): Max retries exceeded with url: /v2/keys/services/BattleAllocatorStub/127.0.0.1%7C9000 (Caused by NewConnectionError('<urllib3.connection.HTTPConnection object at 0x0000022416221760>: Failed to establish a new connection: [WinError 10061] 由于目标计算机积极拒绝，无法连接。')), traceback:<class 'requests.exceptions.ConnectionError'>
HTTPConnectionPool(host='127.0.0.1', port=2379): Max retries exceeded with url: /v2/keys/services/BattleAllocatorStub/127.0.0.1%7C9000 (Caused by NewConnectionError('<urllib3.connection.HTTPConnection object at 0x0000022416221760>: Failed to establish a new connection: [WinError 10061] 由于目标计算机积极拒绝，无法连接。'))
  File "D:\Documents\github\realtime-server\pycharm2020.1.3\script\core\EtcdSupport.py", line 143, in _do_regist
    locals={'self': <core.EtcdSupport.ServiceRegister object at 0x0000022416170D90>, 'service_name': 'BattleAllocatorStub', 'data': 'ttl=180', 'now_url': 'http://127.0.0.1:2379/v2/keys/services/BattleAllocatorStub/127.0.0.1|9000'}
  File "C:\Program Files\Python38\lib\concurrent\futures\thread.py", line 57, in run
    locals={}
  File "D:\Documents\github\realtime-server\pycharm2020.1.3\script\core\EtcdSupport.py", line 144, in <lambda>
    locals={'data': 'ttl=180', 'now_url': 'http://127.0.0.1:2379/v2/keys/services/BattleAllocatorStub/127.0.0.1|9000'}
  File "C:\Program Files\Python38\lib\site-packages\requests\api.py", line 61, in request
    locals={'method': 'PUT', 'url': 'http://127.0.0.1:2379/v2/keys/services/BattleAllocatorStub/127.0.0.1|9000', 'kwargs': {'data': 'ttl=180', 'headers': {'Content-Type': 'application/x-www-form-urlencoded'}, 'timeout': 2}, 'session': <requests.sessions.Session object at 0x000002241620F940>}
  File "C:\Program Files\Python38\lib\site-packages\requests\sessions.py", line 542, in request
    locals={'self': <requests.sessions.Session object at 0x000002241620F940>, 'method': 'PUT', 'url': 'http://127.0.0.1:2379/v2/keys/services/BattleAllocatorStub/127.0.0.1|9000', 'params': None, 'data': 'ttl=180', 'headers': {'Content-Type': 'application/x-www-form-urlencoded'}, 'cookies': None, 'files': None, 'auth': None, 'timeout': 2, 'allow_redirects': True, 'proxies': {}, 'hooks': None, 'stream': None, 'verify': None, 'cert': None, 'json': None, 'req': <Request [PUT]>, 'prep': <PreparedRequest [PUT]>, 'settings': {'verify': True, 'proxies': OrderedDict(), 'stream': False, 'cert': None}, 'send_kwargs': {'timeout': 2, 'allow_redirects': True, 'verify': True, 'proxies': OrderedDict(), 'stream': False, 'cert': None}}
  File "C:\Program Files\Python38\lib\site-packages\requests\sessions.py", line 655, in send
    locals={'self': <requests.sessions.Session object at 0x000002241620F940>, 'request': <PreparedRequest [PUT]>, 'kwargs': {'timeout': 2, 'verify': True, 'proxies': OrderedDict(), 'stream': False, 'cert': None}, 'allow_redirects': True, 'stream': False, 'hooks': {'response': []}, 'adapter': <requests.adapters.HTTPAdapter object at 0x0000022416221B80>, 'start': 1.215380078}
  File "C:\Program Files\Python38\lib\site-packages\requests\adapters.py", line 516, in send
    locals={'self': <requests.adapters.HTTPAdapter object at 0x0000022416221B80>, 'request': <PreparedRequest [PUT]>, 'stream': False, 'timeout': Timeout(connect=2, read=2, total=None), 'verify': True, 'cert': None, 'proxies': OrderedDict(), 'conn': <urllib3.connectionpool.HTTPConnectionPool object at 0x0000022416181D30>, 'url': '/v2/keys/services/BattleAllocatorStub/127.0.0.1%7C9000', 'chunked': False}
